Workbook

Sheet Cover
A1: ATLAS | API 579-1/ASME FFS-1 2021 PART 9 - CRACK-LIKE FLAW ASSESSMENT
A2: ="KPSCL1 (9B.3.2) / KPSCL2 (9B.3.3) / RPSCL (9C.3.2) - plate with infinite-length surface crack - VARIABLE AMPLITUDE LOADING - "&IF(UNIT_SYSTEM="SI","SI UNITS (mm, MPa, MPa√m, °C)","FPS / US CUSTOMARY UNITS (in, ksi, ksi√in, °F)") -> KPSCL1 (9B.3.2) / KPSCL2 (9B.3.3) / RPSCL (9C.3.2) - plate with infinite-length surface crack - VARIABLE AMPLITUDE LOADING - SI UNITS (mm, MPa, MPa√m, °C)
A4: UNIT SYSTEM - SELECT FIRST (governs inputs, databases, results, plots)
A5: Unit system | B5: SI | C5: =IF(UNIT_SYSTEM="SI","SI - length mm, stress MPa, K MPa√m, temperature °C, J kJ/m², da/dN mm/cycle","FPS - length in, stress ksi, K ksi√in, temperature °F, J in-lb/in², da/dN in/cycle") -> SI - length mm, stress MPa, K MPa√m, temperature °C, J kJ/m², da/dN mm/cycle
A6: Template default values (formulas) convert automatically when the unit system is changed. Values you type are taken in the selected system; to switch units on a case with typed values run: python ENGINE/tools/convert_units.py <workbook> --to FPS|SI
A8: CASE IDENTIFICATION
A9: Project | B9: ATLAS KPSCL reference case
A10: Component / tag | B10: Flat plate (Fig. 9B.2(b))
A11: Flaw location | B11: Infinite-length surface flaw
A12: Analyst
A13: Checker
A14: Date
A15: Revision | B15: R1
A16: Crack geometry | B16: KPSCL
A17: Load type | B17: VARIABLE
A19: COLOUR LEGEND
A20: Input - edit (blue text, yellow)
A21: Calculated / database look-up (green)
A22: Database (read-only copy of data/*.csv)
A24: WORKFLOW (PART 9 LEVEL 2, PARAGRAPH 9.4.3.2 + 9.5.1)
A25: Sheet | B25: Part 9 step | D25: Content
A26: 1_Geometry_Flaw | B26: STEP 5 / 9.3.6 | D26: Plate t; measured flaw depth a (infinite length), 0 < a/t <= 0.8
A27: 2_Material | B27: STEP 3 | D27: Material from database, strengths at assessment temperature, Fig. 9.19 cut-off
A28: 3_Toughness | B28: STEP 4 / Annex 9F | D28: Kmat route: project, Table 9F.1 tests, 9F.4.2-9F.4.7, 9F.4.12
A29: 4_Crack_Growth | B29: 9.5.1 / Annex 9F.5 | D29: Growth model (Tables 9F.4-9F.9, Eqs. 9F.135-9F.169)
A30: 5_Loads | B30: STEPs 1-2 / 9C.2.2 | D30: Stress distribution (Fourth Order Polynomial - KPSCL1 / Arbitrary - KPSCL2) and input format
A31: 5B_Stress_Profile | B31: 9B.2.2 / 9B.14 | D31: Arbitrary through-wall stress profile (primary, secondary, residual)
A32: 6_Residual_Stress | B32: Annex 9D | D32: None / user / Annex 9D PWHT, as-welded, uniform yield / user profile
A33: 7_Load_History | B33: 9.5.1.1(e) | D33: Load blocks (min/max scale, cycles per block)
A34: 8_Controls | B34: Numerics / 9.5.1.2 | D34: Integration controls and remaining-life acceptance
A35: 9_Level3 | B35: 9.4.4 Level 3 | D35: Method A sensitivity / partial safety factors, Method D ductile tearing (J-R curve)
A37: HOW TO RUN
A38: 1. Select the unit system, edit only yellow cells (use the drop-downs) and save the workbook.
A39: 2. python RUN_THIS_CASE.py (or from the package root: python ENGINE/run_case.py)
A40: 3. Results appear in OUTPUT/ (output workbook - open Dashboard first) and PLOTS/ (images + plot-data workbook),
A41: in the selected unit system only. Each run replaces the previous results of this case.
A42: 4. Database sheets are display copies of ENGINE/data/*.csv, which the solver always uses.

Sheet 1_Geometry_Flaw
A1: ="GEOMETRY FLAW - KPSCL1 / KPSCL2 / RPSCL ("&UNIT_SYSTEM&" UNITS)" -> GEOMETRY FLAW - KPSCL1 / KPSCL2 / RPSCL (SI UNITS)
A2: Figure 9B.2(b): plate thickness t, surface crack of depth a and infinite length
A3: Parameter | B3: Value | C3: Unit | D3: API 579 reference / note | E3: Status
A4: PLATE GEOMETRY (Figure 9B.2(b))
A5: Plate thickness, t | B5: =IF(UNIT_SYSTEM="SI",20,0.78740157480315) -> 20 | C5: =IF(UNIT_SYSTEM="SI","mm","in") -> mm | E5: INPUT
A6: FLAW CHARACTERIZATION (paragraph 9.3.6.3)
A7: Measured flaw depth, a | B7: =IF(UNIT_SYSTEM="SI",3,0.118110236220472) -> 3 | C7: =IF(UNIT_SYSTEM="SI","mm","in") -> mm | D7: Depth from the cracked surface (9.3.6.3); 0 < a/t <= 0.8 | E7: INPUT
A8: Measured flaw length 2c (information) | C8: =IF(UNIT_SYSTEM="SI","mm","in") -> mm | D8: Infinite length is assumed - a conservative bound for long surface flaws | E8: INPUT
A9: RESULTING ASSESSMENT FLAW
A10: Assessment depth a0 | B10: =in_a_m -> 3 | C10: =IF(UNIT_SYSTEM="SI","mm","in") -> mm | D10: Used as initial crack depth | E10: CALC
A11: a0/t | B11: =in_a_m/in_t -> 0.15 | C11: - | D11: 9B.3.2.2(d): 0 < a/t <= 0.8 | E11: CALC
A12: KPSCL applicability | B12: =IF(AND(calc_at>0,calc_at<=0.8),"OK","OUT OF RANGE") -> OK | E12: CALC
A13: Influence coefficient G0 at a0 | B13: =1.1202+6.0061*calc_at^2-1.3891*calc_at^4+7.926*calc_at^6+31.914*calc_at^8 -> 1.2547325 | C13: - | D13: Eq. 9B.13, Table 9B.2 | E13: CALC
A14: Influence coefficient G1 at a0 | B14: =0.68109+2.3137*calc_at^2-0.71895*calc_at^4+3.114*calc_at^6+10.702*calc_at^8 -> 0.73282249 | C14: - | D14: Eq. 9B.13, Table 9B.2 | E14: CALC
A15: Infinite length is a conservative bound for a long surface flaw. No restraint on the plate ends is assumed (9B.3.2.2(e)); the reference stress uses Eq. 9C.31 (negligible bending restraint).

Sheet 2_Material
A1: ="MATERIAL - KPSCL1 / KPSCL2 / RPSCL ("&UNIT_SYSTEM&" UNITS)" -> MATERIAL - KPSCL1 / KPSCL2 / RPSCL (SI UNITS)
A2: Paragraph 9.4.3.2 STEP 3 (strength) and Figure 9.19 (FAD cut-off). Database: DB_Materials
A3: Parameter | B3: Value | C3: Unit | D3: API 579 reference / note | E3: Status
A4: MATERIAL SELECTION
A5: Material class filter (narrows the Material ID list) | B5: ALL | C5: - | D5: Select a class, then pick the Material ID from the filtered drop-down | E5: INPUT
A6: Material ID | B6: REFERENCE_CS_350 | C6: - | D6: Select from DB_Materials | E6: INPUT
A7: Selected ID in filtered class? | B7: =IF(in_material_filter="ALL","OK",IF(ISNUMBER(MATCH(in_material_id,INDIRECT("L_MAT_"&in_material_filter),0)),"OK","NOT IN CLASS - reselect ID")) -> OK | D7: Check only - the solver uses the Material ID | E7: CALC
A8: Specification | B8: =IFERROR(INDEX(DB_Materials!$B:$B,MATCH(in_material_id,DB_Materials!$A:$A,0)),"") -> REFERENCE | E8: CALC
A9: Grade / class | B9: =IFERROR(INDEX(DB_Materials!$C:$C,MATCH(in_material_id,DB_Materials!$A:$A,0)),"") -> 350 MPa yield | E9: CALC
A10: Product form | B10: =IFERROR(INDEX(DB_Materials!$D:$D,MATCH(in_material_id,DB_Materials!$A:$A,0)),"") -> Generic | E10: CALC
A11: Condition / heat treatment | B11: =IFERROR(INDEX(DB_Materials!$E:$E,MATCH(in_material_id,DB_Materials!$A:$A,0)),"") -> - | E11: CALC
A12: Material class | B12: =IFERROR(INDEX(DB_Materials!$F:$F,MATCH(in_material_id,DB_Materials!$A:$A,0)),"") -> REFERENCE | D12: Table 9.2 class / route checks | E12: CALC
A13: SMYS (specified minimum) | B13: =IFERROR(INDEX(DB_Materials!$G:$G,MATCH(in_material_id,DB_Materials!$A:$A,0)),"") -> 350 | C13: =IF(UNIT_SYSTEM="SI","MPa","ksi") -> MPa | D13: Ambient, per material specification | E13: CALC
A14: SMTS (specified minimum) | B14: =IFERROR(INDEX(DB_Materials!$H:$H,MATCH(in_material_id,DB_Materials!$A:$A,0)),"") -> 500 | C14: =IF(UNIT_SYSTEM="SI","MPa","ksi") -> MPa | D14: Ambient, per material specification | E14: CALC
A15: Typical E (ambient) | B15: =IFERROR(INDEX(DB_Materials!$I:$I,MATCH(in_material_id,DB_Materials!$A:$A,0)),"") -> 200000 | C15: =IF(UNIT_SYSTEM="SI","MPa","ksi") -> MPa | D15: Typical - confirm with Annex 2E / ASME II-D | E15: CALC
A16: ASME exemption curve | B16: =IFERROR(INDEX(DB_Materials!$J:$J,MATCH(in_material_id,DB_Materials!$A:$A,0)),"") -> N/A | D16: Part 3 Table 3.2 | E16: CALC
A17: Lr(max) category | B17: =IFERROR(INDEX(DB_Materials!$K:$K,MATCH(in_material_id,DB_Materials!$A:$A,0)),"") -> FLOW_STRESS | D17: Figure 9.19 Note 2 | E17: CALC
A18: Default growth model | B18: =IFERROR(INDEX(DB_Materials!$L:$L,MATCH(in_material_id,DB_Materials!$A:$A,0)),"") -> PROJECT_MATERIAL_DATA | D18: Used when 4_Crack_Growth = FROM_MATERIAL_DB | E18: CALC
A19: Suggested toughness method | B19: =IFERROR(INDEX(DB_Materials!$M:$M,MATCH(in_material_id,DB_Materials!$A:$A,0)),"") -> PROJECT_KMAT | D19: Informative | E19: CALC
A20: Database note | B20: =IFERROR(INDEX(DB_Materials!$S:$S,MATCH(in_material_id,DB_Materials!$A:$A,0)),"") -> ATLAS KPTC regression dataset (R1-R7 baseline). Not a material specification. FPS values are exact conversions. | E20: CALC
A21: STRENGTH AT ASSESSMENT CONDITION (STEP 3)
A22: Strength source (9.4.3.2 STEP 3) | B22: DATABASE_SPEC_MIN | C22: - | D22: Spec minimum (database) or approved values at assessment temperature | E22: INPUT
A23: Project yield strength at temperature, Sy | C23: =IF(UNIT_SYSTEM="SI","MPa","ksi") -> MPa | D23: Used when PROJECT_AT_TEMPERATURE | E23: INPUT
A24: Project tensile strength at temperature, Su | C24: =IF(UNIT_SYSTEM="SI","MPa","ksi") -> MPa | D24: Used when PROJECT_AT_TEMPERATURE | E24: INPUT
A25: Project data status | B25: NOT_APPROVED | C25: - | D25: Set APPROVED for any project-entered data | E25: INPUT
A26: Yield strength used, Sy | B26: =IF(in_strength_source="PROJECT_AT_TEMPERATURE",in_sy_project,db_SMYS) -> 350 | C26: =IF(UNIT_SYSTEM="SI","MPa","ksi") -> MPa | E26: CALC
A27: Tensile strength used, Su | B27: =IF(in_strength_source="PROJECT_AT_TEMPERATURE",in_su_project,db_SMTS) -> 500 | C27: =IF(UNIT_SYSTEM="SI","MPa","ksi") -> MPa | E27: CALC
A28: FAD CUT-OFF AND CONSTRAINT
A29: FAD cut-off Lr(max) category (Fig. 9.19) | B29: FROM_DATABASE | C29: - | E29: INPUT
A30: Constraint for Eq. 9.13/9.14 | B30: plane_strain | C30: - | E30: INPUT
A31: Lr(max) category used | B31: =IF(in_lrmax_mode="FROM_DATABASE",db_lrmax_category,in_lrmax_mode) -> FLOW_STRESS | E31: CALC
A32: Lr(max) cut-off | B32: =IFERROR(IF(IF(in_lrmax_mode="FROM_DATABASE",db_lrmax_category,in_lrmax_mode)="FLOW_STRESS",(calc_sy+calc_su)/(2*calc_sy),VALUE(INDEX(DB_Lr_max!$B:$B,MATCH(IF(in_lrmax_mode="FROM_DATABASE",db_lrmax_category,in_lrmax_mode),DB_Lr_max!$A:$A,0)))),"") -> 1.2142857 | C32: - | D32: Flow stress (Sy+Su)/2 / Sy for FLOW_STRESS (Note 2(e)) | E32: CALC
A33: TEMPERATURE AND ELASTIC PROPERTIES
A34: Assessment temperature, T | B34: =IF(UNIT_SYSTEM="SI",25,77) -> 25 | C34: =IF(UNIT_SYSTEM="SI","°C","°F") -> °C | E34: INPUT
A35: Elastic modulus at T, E | B35: =IF(UNIT_SYSTEM="SI",200000,29007.5475460418) -> 200000 | C35: =IF(UNIT_SYSTEM="SI","MPa","ksi") -> MPa | D35: Typical values in DB; confirm with Annex 2E / ASME II-D | E35: INPUT
A36: Poisson's ratio, nu | B36: 0.3 | C36: - | E36: INPUT

Sheet 3_Toughness
A1: ="TOUGHNESS - KPSCL1 / KPSCL2 / RPSCL ("&UNIT_SYSTEM&" UNITS)" -> TOUGHNESS - KPSCL1 / KPSCL2 / RPSCL (SI UNITS)
A2: Paragraph 9.4.3.2 STEP 4 and Annex 9F.4. Only the inputs of the selected method are used.
A3: Parameter | B3: Value | C3: Unit | D3: API 579 reference / note | E3: Status | G3: Test # | H3: =IF(UNIT_SYSTEM="SI","K (MPa√m)","K (ksi√in)") -> K (MPa√m)
A4: METHOD SELECTION | G4: 1
A5: Toughness method (Part 9 STEP 4) | B5: PROJECT_KMAT | C5: - | E5: INPUT | G5: 2
A6: Clause | B6: =IFERROR(INDEX(DB_Toughness!$B:$B,MATCH(in_method,DB_Toughness!$A:$A,0)),"") -> 9.3.5.2 | E6: CALC | G6: 3
A7: Method summary | B7: =IFERROR(INDEX(DB_Toughness!$E:$E,MATCH(in_method,DB_Toughness!$A:$A,0)),"") -> Approved measured/project Kmat, or Kmat stored in the material record | E7: CALC | G7: 4
A8: PROJECT_KMAT (9.3.5.2) | G8: 5
A9: Project Kmat (approved) | C9: =IF(UNIT_SYSTEM="SI","MPa√m","ksi√in") -> MPa√m | D9: PROJECT_KMAT when the material record has no Kmat | E9: INPUT | G9: 6
A10: PROJECT_TEST_SET (Table 9F.1, enter results in column H) | G10: 7
A11: Number of tests | B11: =COUNT($H$4:$H$33) -> 0 | C11: - | D11: 3 to 30 tests | E11: CALC | G11: 8
A12: Equivalent minimum-of-three | B12: =IF(COUNT($H$4:$H$33)<3,"n < 3",SMALL($H$4:$H$33,INT((COUNT($H$4:$H$33)-1)/5)+1)) -> n < 3 | C12: =IF(UNIT_SYSTEM="SI","MPa√m","ksi√in") -> MPa√m | D12: Table 9F.1 rank: 3-5 lowest, 6-10 2nd lowest, ... | E12: CALC | G12: 9
A13: Scatter check (3 tests, Note 2) | B13: =IF(COUNT($H$4:$H$33)<>3,"-",IF(OR(MIN($H$4:$H$33)<0.7*AVERAGE($H$4:$H$33),MAX($H$4:$H$33)>1.4*AVERAGE($H$4:$H$33)),"EXCESSIVE","OK")) -> - | E13: CALC | G13: 10
A14: 9F412_AUSTENITIC_JC (9F.4.12, Table 9F.2) | G14: 11
A15: 9F.2 austenitic condition | B15: WROUGHT | C15: - | E15: INPUT | G15: 12
A16: 9F.2 Jc basis | B16: LOWER | C16: - | D16: LOWER = 90/95 lower bound | E16: INPUT | G16: 13
A17: 9F42_ASME_XI_LOWER (9F.4.2) | G17: 14
A18: Reference temperature mode (9F.4.2.2) | B18: EQ_9F29 | C18: - | E18: INPUT | G18: 15
A19: Tref / RTNDT (DIRECT) | B19: =IF(UNIT_SYSTEM="SI",0,32) -> 0 | C19: =IF(UNIT_SYSTEM="SI","°C","°F") -> °C | E19: INPUT | G19: 16
A20: ASME exemption curve (Part 3 Table 3.2) | B20: FROM_DATABASE | C20: - | E20: INPUT | G20: 17
A21: Section XI curve | B21: KIC | C21: - | D21: KIC Eq. 9F.44 / KIR Eq. 9F.46 | E21: INPUT | G21: 18
A22: Upper-shelf truncation 9F.4.2.1(e) | B22: =IF(UNIT_SYSTEM="SI",110,100) -> 110 | C22: =IF(UNIT_SYSTEM="SI","MPa√m","ksi√in") -> MPa√m | D22: SI: 110 or 220 MPa√m. FPS: 100 or 200 ksi√in | E22: INPUT | G22: 19
A23: Exemption curve used | B23: =IF(in_curve_mode="FROM_DATABASE",db_exemption_curve,in_curve_mode) -> N/A | D23: Also used by Master Curve Option A | E23: CALC | G23: 20
A24: 9F43_MASTER_CURVE (9F.4.3) - also base for 9F45 / 9F47 | G24: 21
A25: Master Curve T0 mode (9F.4.3.2) | B25: OPTION_A_EXEMPTION | C25: - | E25: INPUT | G25: 22
A26: Master Curve T0 (DIRECT) | B26: =IF(UNIT_SYSTEM="SI",0,32) -> 0 | C26: =IF(UNIT_SYSTEM="SI","°C","°F") -> °C | E26: INPUT | G26: 23
A27: Ambient yield strength, SyA | B27: =IF(UNIT_SYSTEM="SI",350,50.7632082055732) -> 350 | C27: =IF(UNIT_SYSTEM="SI","MPa","ksi") -> MPa | D27: Option A T0 (Eq. 9F.54/57) and 9F.4.5 | E27: INPUT | G27: 24
A28: Carbon steel sulfur class | B28: LOW | C28: - | D28: LOW <= 0.01 % S | E28: INPUT | G28: 25
A29: Option D test temperature | B29: =IF(UNIT_SYSTEM="SI",0,32) -> 0 | C29: =IF(UNIT_SYSTEM="SI","°C","°F") -> °C | E29: INPUT | G29: 26
A30: Option D test Jcrit | B30: =IF(UNIT_SYSTEM="SI",50,285.507415198588) -> 50 | C30: =IF(UNIT_SYSTEM="SI","kJ/m²","in-lb/in²") -> kJ/m² | E30: INPUT | G30: 27
A31: Option D E at test temperature | B31: =IF(UNIT_SYSTEM="SI",200000,29007.5475460418) -> 200000 | C31: =IF(UNIT_SYSTEM="SI","MPa","ksi") -> MPa | E31: INPUT | G31: 28
A32: Option D Poisson's ratio | B32: 0.3 | C32: - | E32: INPUT | G32: 29
A33: Option D specimen thickness B | B33: =IF(UNIT_SYSTEM="SI",25,0.984251968503937) -> 25 | C33: =IF(UNIT_SYSTEM="SI","mm","in") -> mm | E33: INPUT | G33: 30
A34: Master Curve probability Pf | B34: 0.05 | C34: - | D34: 0.05 = recommended 5 % lower bound | E34: INPUT
A35: Crack-front length L mode | B35: AUTO | C35: - | D35: AUTO: 2t (through-wall crack) or 100 mm / 4 in (infinite surface crack, Eq. 9H.15) | E35: INPUT
A36: Crack-front length L (USER) | B36: =IF(UNIT_SYSTEM="SI",40,1.5748031496063) -> 40 | C36: =IF(UNIT_SYSTEM="SI","mm","in") -> mm | E36: INPUT
A37: Limit Master Curve by 9F.4.4 upper shelf | B37: NONE | C37: - | E37: INPUT
A38: Hydrogen T0 shift (9F.4.6.2) | B38: NONE | C38: - | D38: H > 1 ppm: 2.25Cr-1Mo +50 C; CS/low-Cr use 9F45_ARREST | E38: INPUT
A39: User hydrogen T0 shift | B39: 0 | C39: =IF(UNIT_SYSTEM="SI","°C","°F") -> °C | E39: INPUT
A40: 9F44_UPPER_SHELF (9F.4.4)
...

Sheet 4_Crack_Growth
A1: ="CRACK GROWTH - KPSCL1 / KPSCL2 / RPSCL ("&UNIT_SYSTEM&" UNITS)" -> CRACK GROWTH - KPSCL1 / KPSCL2 / RPSCL (SI UNITS)
A2: Paragraph 9.5.1 and Annex 9F.5. Database: DB_Growth (Tables 9F.4-9F.9 and 9F.5.3.9 equations)
A3: Parameter | B3: Value | C3: Unit | D3: API 579 reference / note | E3: Status
A4: MODEL SELECTION
A5: Crack growth model | B5: FROM_MATERIAL_DB | C5: - | E5: INPUT
A6: Model used | B6: =IF(in_growth_model="FROM_MATERIAL_DB",db_default_growth_model,in_growth_model) -> PROJECT_MATERIAL_DATA | E6: CALC
A7: API table | B7: =IFERROR(IF(INDEX(DB_Growth!$C:$C,MATCH(calc_gm,DB_Growth!$A:$A,0))="","-",INDEX(DB_Growth!$C:$C,MATCH(calc_gm,DB_Growth!$A:$A,0))),"-") -> Material DB | E7: CALC
A8: Equation | B8: =IFERROR(IF(INDEX(DB_Growth!$D:$D,MATCH(calc_gm,DB_Growth!$A:$A,0))="","-",INDEX(DB_Growth!$D:$D,MATCH(calc_gm,DB_Growth!$A:$A,0))),"-") -> PARIS_9F135 | E8: CALC
A9: Description | B9: =IFERROR(IF(INDEX(DB_Growth!$E:$E,MATCH(calc_gm,DB_Growth!$A:$A,0))="","-",INDEX(DB_Growth!$E:$E,MATCH(calc_gm,DB_Growth!$A:$A,0))),"-") -> C, n, dKth from selected material record | E9: CALC
A10: Applicability | B10: =IFERROR(IF(INDEX(DB_Growth!$F:$F,MATCH(calc_gm,DB_Growth!$A:$A,0))="","-",INDEX(DB_Growth!$F:$F,MATCH(calc_gm,DB_Growth!$A:$A,0))),"-") -> Approved material-specific data | E10: CALC
A11: C1 (first / R<0.5 row) | B11: =IFERROR(IF(calc_gm="PROJECT_MATERIAL_DATA",INDEX(DB_Materials!$O:$O,MATCH(in_material_id,DB_Materials!$A:$A,0)),IF(calc_gm="PROJECT_USER_PARIS","see below",IF(INDEX(DB_Growth!$G:$G,MATCH(calc_gm,DB_Growth!$A:$A,0))="","-",INDEX(DB_Growth!$G:$G,MATCH(calc_gm,DB_Growth!$A:$A,0))))),"-") -> 2e-09 | C11: =IF(UNIT_SYSTEM="SI","mm/cycle","in/cycle") -> mm/cycle | D11: For 9F.7 models a second R>=0.5 parameter row exists (DB_Growth) | E11: CALC
A12: n1 | B12: =IFERROR(IF(calc_gm="PROJECT_MATERIAL_DATA",INDEX(DB_Materials!$P:$P,MATCH(in_material_id,DB_Materials!$A:$A,0)),IF(calc_gm="PROJECT_USER_PARIS","see below",IF(INDEX(DB_Growth!$H:$H,MATCH(calc_gm,DB_Growth!$A:$A,0))="","-",INDEX(DB_Growth!$H:$H,MATCH(calc_gm,DB_Growth!$A:$A,0))))),"-") -> 3 | C12: - | E12: CALC
A13: C2 (bilinear) | B13: =IFERROR(IF(INDEX(DB_Growth!$I:$I,MATCH(calc_gm,DB_Growth!$A:$A,0))="","-",INDEX(DB_Growth!$I:$I,MATCH(calc_gm,DB_Growth!$A:$A,0))),"-") -> - | C13: =IF(UNIT_SYSTEM="SI","mm/cycle","in/cycle") -> mm/cycle | E13: CALC
A14: n2 | B14: =IFERROR(IF(INDEX(DB_Growth!$J:$J,MATCH(calc_gm,DB_Growth!$A:$A,0))="","-",INDEX(DB_Growth!$J:$J,MATCH(calc_gm,DB_Growth!$A:$A,0))),"-") -> - | C14: - | E14: CALC
A15: dK transition | B15: =IFERROR(IF(INDEX(DB_Growth!$K:$K,MATCH(calc_gm,DB_Growth!$A:$A,0))="","-",INDEX(DB_Growth!$K:$K,MATCH(calc_gm,DB_Growth!$A:$A,0))),"-") -> - | C15: =IF(UNIT_SYSTEM="SI","MPa√m","ksi√in") -> MPa√m | E15: CALC
A16: Threshold dKth | B16: =IFERROR(IF(calc_gm="PROJECT_MATERIAL_DATA",INDEX(DB_Materials!$Q:$Q,MATCH(in_material_id,DB_Materials!$A:$A,0)),IF(calc_gm="PROJECT_USER_PARIS","see below",IF(INDEX(DB_Growth!$L:$L,MATCH(calc_gm,DB_Growth!$A:$A,0))="","-",INDEX(DB_Growth!$L:$L,MATCH(calc_gm,DB_Growth!$A:$A,0))))),"-") -> 5 | C16: =IF(UNIT_SYSTEM="SI","MPa√m","ksi√in") -> MPa√m | E16: CALC
A17: OPTIONS
A18: Stress ratio R basis | B18: INCLUDE_RESIDUAL | C18: - | D18: FORCE_R_GE_0_5 = 9F.5.3.8 recommendation for as-welded joints | E18: INPUT
A19: Welded-joint equation (Table 9F.5) | B19: 9F140 | C19: - | D19: Table 9F.5 comment: Eq. 9F.140 | E19: INPUT
A20: Temperature correction R_E (9F.139) | B20: AUTO | C20: - | D20: AUTO = only where the table specifies 9F.137 | E20: INPUT
A21: E at ambient, Ey | B21: =IF(UNIT_SYSTEM="SI",200000,29007.5475460418) -> 200000 | C21: =IF(UNIT_SYSTEM="SI","MPa","ksi") -> MPa | E21: INPUT
A22: E at temperature, EyT | B22: =IF(UNIT_SYSTEM="SI",200000,29007.5475460418) -> 200000 | C22: =IF(UNIT_SYSTEM="SI","MPa","ksi") -> MPa | E22: INPUT
A23: H2S concentration (sour crude) | B23: 0 | C23: ppm | D23: ppm, Eqs. 9F.160/9F.162 | E23: INPUT
A24: Threshold override dKth (blank = table) | C24: =IF(UNIT_SYSTEM="SI","MPa√m","ksi√in") -> MPa√m | E24: INPUT
A25: R_E = max(Ey/EyT, 1) | B25: =MAX(in_E_ambient/in_E_temp,1) -> 1 | C25: - | D25: Eq. 9F.139 | E25: CALC
A26: PROJECT_USER_PARIS (requires 2_Material data status = APPROVED)
A27: Project Paris C (PROJECT_USER_PARIS) | C27: =IF(UNIT_SYSTEM="SI","mm/cycle","in/cycle") -> mm/cycle | D27: da/dN in mm/cycle (in/cycle) with dK in MPa√m (ksi√in) | E27: INPUT
A28: Project Paris n | C28: - | E28: INPUT
A29: Project threshold dKth | C29: =IF(UNIT_SYSTEM="SI","MPa√m","ksi√in") -> MPa√m | E29: INPUT

Sheet 5_Loads
A1: ="LOADS - KPSCL1 / KPSCL2 / RPSCL ("&UNIT_SYSTEM&" UNITS)" -> LOADS - KPSCL1 / KPSCL2 / RPSCL (SI UNITS)
A2: STEP 1-2: stresses normal to the crack plane, uncracked component. Values at load scale = 1.0 (scaled by 7_Load_History).
A3: Parameter | B3: Value | C3: Unit | D3: API 579 reference / note | E3: Status
A4: STRESS DISTRIBUTION (API 579 Annex 9B / 9C - plate, surface crack, infinite length)
A5: Through-wall stress distribution (Annex 9B / 9C) | B5: Through-Wall Fourth Order Polynomial Stress Distribution - KPSCL1 (9B.3.2) / RPSCL (9C.3.2) | C5: - | D5: Selects the stress intensity solution (KPSCL1 or KPSCL2) and reference stress (RPSCL) | E5: INPUT
A6: Stress input format | B6: Polynomial coefficients (sigma0 to sigma4) | C6: - | D6: Options depend on the distribution: Membrane + Bending is available for both | E6: INPUT
A7: Solution code | B7: =IF(ISNUMBER(SEARCH("KPSCL2",in_stress_dist)),"KPSCL2","KPSCL1") -> KPSCL1 | E7: CALC
A8: Stress intensity factor solution | B8: =IF(calc_sif="KPSCL2","KPSCL2 - weight function, Eqs. 9B.261-9B.269 (9B.3.3)","KPSCL1 - Eq. 9B.12 with G0-G4 (9B.3.2)") -> KPSCL1 - Eq. 9B.12 with G0-G4 (9B.3.2) | E8: CALC
A9: Reference stress solution | B9: =IF(calc_sif="KPSCL2","RPSCL (9C.3.3 -> 9C.3.2), Eq. 9C.31","RPSCL (9C.3.2), Eq. 9C.31") -> RPSCL (9C.3.2), Eq. 9C.31 | E9: CALC
A10: Enter the stresses in | B10: =IF(ISNUMBER(SEARCH("Membrane",in_stress_input)),"Section MEMBRANE + BENDING below",IF(ISNUMBER(SEARCH("Polynomial",in_stress_input)),"Section FOURTH-ORDER POLYNOMIAL below",IF(ISNUMBER(SEARCH("profile",in_stress_input)),"Sheet 5B_Stress_Profile","Select the stress input format"))) -> Section FOURTH-ORDER POLYNOMIAL below | E10: CALC
A11: Selection check | B11: =IF(AND(calc_sif="KPSCL1",ISNUMBER(SEARCH("profile",in_stress_input))),"NOT VALID - a point profile needs the Arbitrary distribution (KPSCL2)","OK") -> OK | E11: CALC
A12: MEMBRANE + BENDING (used when the input format is Membrane + Bending)
A13: Primary membrane stress, Pm | B13: =IF(UNIT_SYSTEM="SI",120,17.4045285276251) -> 120 | C13: =IF(UNIT_SYSTEM="SI","MPa","ksi") -> MPa | E13: INPUT
A14: Primary bending stress, Pb | B14: =IF(UNIT_SYSTEM="SI",30,4.35113213190628) -> 30 | C14: =IF(UNIT_SYSTEM="SI","MPa","ksi") -> MPa | E14: INPUT
A15: Secondary membrane stress, Sm | B15: =IF(UNIT_SYSTEM="SI",20,2.90075475460418) -> 20 | C15: =IF(UNIT_SYSTEM="SI","MPa","ksi") -> MPa | E15: INPUT
A16: Secondary bending stress, Sb | B16: =IF(UNIT_SYSTEM="SI",10,1.45037737730209) -> 10 | C16: =IF(UNIT_SYSTEM="SI","MPa","ksi") -> MPa | E16: INPUT
A17: FOURTH-ORDER POLYNOMIAL sigma(x) = s0 + s1(x/t) + ... + s4(x/t)^4 (Eqs. 9B.3 / 9C.3) - used with Polynomial coefficients
A18: Primary polynomial sigma0 | B18: =IF(UNIT_SYSTEM="SI",150,21.7556606595314) -> 150 | C18: =IF(UNIT_SYSTEM="SI","MPa","ksi") -> MPa | E18: INPUT
A19: Primary polynomial sigma1 | B19: =IF(UNIT_SYSTEM="SI",-60,-8.70226426381255) -> -60 | C19: =IF(UNIT_SYSTEM="SI","MPa","ksi") -> MPa | E19: INPUT
A20: Primary polynomial P2 | B20: 0 | C20: =IF(UNIT_SYSTEM="SI","MPa","ksi") -> MPa | E20: INPUT
A21: Primary polynomial P3 | B21: 0 | C21: =IF(UNIT_SYSTEM="SI","MPa","ksi") -> MPa | E21: INPUT
A22: Primary polynomial P4 | B22: 0 | C22: =IF(UNIT_SYSTEM="SI","MPa","ksi") -> MPa | E22: INPUT
A23: Secondary polynomial sigma0 | B23: =IF(UNIT_SYSTEM="SI",30,4.35113213190628) -> 30 | C23: =IF(UNIT_SYSTEM="SI","MPa","ksi") -> MPa | E23: INPUT
A24: Secondary polynomial sigma1 | B24: =IF(UNIT_SYSTEM="SI",-20,-2.90075475460418) -> -20 | C24: =IF(UNIT_SYSTEM="SI","MPa","ksi") -> MPa | E24: INPUT
A25: Secondary polynomial Q2 | B25: 0 | C25: =IF(UNIT_SYSTEM="SI","MPa","ksi") -> MPa | E25: INPUT
A26: Secondary polynomial Q3 | B26: 0 | C26: =IF(UNIT_SYSTEM="SI","MPa","ksi") -> MPa | E26: INPUT
A27: Secondary polynomial Q4 | B27: 0 | C27: =IF(UNIT_SYSTEM="SI","MPa","ksi") -> MPa | E27: INPUT
A28: Primary Pm from polynomial | B28: =in_P0+in_P1/2+in_P2/3+in_P3/4+in_P4/5 -> 120 | C28: =IF(UNIT_SYSTEM="SI","MPa","ksi") -> MPa | D28: Eq. 9C.4 | E28: CALC
A29: Primary Pb from polynomial | B29: =-in_P1/2-in_P2/2-9*in_P3/20-6*in_P4/15 -> 30 | C29: =IF(UNIT_SYSTEM="SI","MPa","ksi") -> MPa | D29: Eq. 9C.5 | E29: CALC
A30: Secondary Sm from polynomial | B30: =in_Q0+in_Q1/2+in_Q2/3+in_Q3/4+in_Q4/5 -> 20 | C30: =IF(UNIT_SYSTEM="SI","MPa","ksi") -> MPa | D30: Eq. 9C.4 | E30: CALC
A31: Secondary Sb from polynomial | B31: =-in_Q1/2-in_Q2/2-9*in_Q3/20-6*in_Q4/15 -> 10 | C31: =IF(UNIT_SYSTEM="SI","MPa","ksi") -> MPa | D31: Eq. 9C.5 | E31: CALC
A32: CRACK-FACE PRESSURE AND REFERENCE STRESS OPTION (all input formats)
A33: Crack-face pressure, pc | B33: 0 | C33: =IF(UNIT_SYSTEM="SI","MPa","ksi") -> MPa | E33: INPUT
A34: Add pc to Pm for reference stress | B34: YES | C34: - | D34: Conservative; engineering option | E34: INPUT

Sheet 5B_Stress_Profile
A1: ="THROUGH-WALL STRESS PROFILE - ARBITRARY DISTRIBUTION ("&UNIT_SYSTEM&" UNITS)" -> THROUGH-WALL STRESS PROFILE - ARBITRARY DISTRIBUTION (SI UNITS)
A2: Stress normal to the crack plane in the uncracked plate, x measured from the cracked surface (0 to t). Used when 5_Loads = Through-Wall Arbitrary Stress Distribution (KPSCL2) with Point-by-point profile (primary, secondary) and/or residual method = USER_PROFILE. Linear between points; the first point must be at x = 0 and the last at x = t. Up to 50 rows; blank rows are ignored.
A3: =IF(UNIT_SYSTEM="SI","x (mm)","x (in)") -> x (mm) | B3: =IF(UNIT_SYSTEM="SI","Primary (MPa)","Primary (ksi)") -> Primary (MPa) | C3: =IF(UNIT_SYSTEM="SI","Secondary (MPa)","Secondary (ksi)") -> Secondary (MPa) | D3: =IF(UNIT_SYSTEM="SI","Residual (MPa)","Residual (ksi)") -> Residual (MPa) | E3: x/t
A4: =IF(UNIT_SYSTEM="SI",0,0) -> 0 | B4: =IF(UNIT_SYSTEM="SI",150,21.7556606595314) -> 150 | C4: =IF(UNIT_SYSTEM="SI",30,4.35113213190628) -> 30 | D4: =IF(UNIT_SYSTEM="SI",20,2.90075475460418) -> 20 | E4: =IF(ISNUMBER(A4),A4/in_t,"") -> 0
A5: =IF(UNIT_SYSTEM="SI",2,0.078740157480315) -> 2 | B5: =IF(UNIT_SYSTEM="SI",144,20.8854342331501) -> 144 | C5: =IF(UNIT_SYSTEM="SI",28,4.06105665644586) -> 28 | D5: =IF(UNIT_SYSTEM="SI",19,2.75571701687398) -> 19 | E5: =IF(ISNUMBER(A5),A5/in_t,"") -> 0.1
A6: =IF(UNIT_SYSTEM="SI",4,0.15748031496063) -> 4 | B6: =IF(UNIT_SYSTEM="SI",138,20.0152078067689) -> 138 | C6: =IF(UNIT_SYSTEM="SI",26,3.77098118098544) -> 26 | D6: =IF(UNIT_SYSTEM="SI",18,2.61067927914377) -> 18 | E6: =IF(ISNUMBER(A6),A6/in_t,"") -> 0.2
A7: =IF(UNIT_SYSTEM="SI",6,0.236220472440945) -> 6 | B7: =IF(UNIT_SYSTEM="SI",132,19.1449813803876) -> 132 | C7: =IF(UNIT_SYSTEM="SI",24,3.48090570552502) -> 24 | D7: =IF(UNIT_SYSTEM="SI",17,2.46564154141356) -> 17 | E7: =IF(ISNUMBER(A7),A7/in_t,"") -> 0.3
A8: =IF(UNIT_SYSTEM="SI",8,0.31496062992126) -> 8 | B8: =IF(UNIT_SYSTEM="SI",126,18.2747549540064) -> 126 | C8: =IF(UNIT_SYSTEM="SI",22,3.1908302300646) -> 22 | D8: =IF(UNIT_SYSTEM="SI",16,2.32060380368335) -> 16 | E8: =IF(ISNUMBER(A8),A8/in_t,"") -> 0.4
A9: =IF(UNIT_SYSTEM="SI",10,0.393700787401575) -> 10 | B9: =IF(UNIT_SYSTEM="SI",120,17.4045285276251) -> 120 | C9: =IF(UNIT_SYSTEM="SI",20,2.90075475460418) -> 20 | D9: =IF(UNIT_SYSTEM="SI",15,2.17556606595314) -> 15 | E9: =IF(ISNUMBER(A9),A9/in_t,"") -> 0.5
A10: =IF(UNIT_SYSTEM="SI",12,0.47244094488189) -> 12 | B10: =IF(UNIT_SYSTEM="SI",114,16.5343021012439) -> 114 | C10: =IF(UNIT_SYSTEM="SI",18,2.61067927914377) -> 18 | D10: =IF(UNIT_SYSTEM="SI",14,2.03052832822293) -> 14 | E10: =IF(ISNUMBER(A10),A10/in_t,"") -> 0.6
A11: =IF(UNIT_SYSTEM="SI",14,0.551181102362205) -> 14 | B11: =IF(UNIT_SYSTEM="SI",108,15.6640756748626) -> 108 | C11: =IF(UNIT_SYSTEM="SI",16,2.32060380368335) -> 16 | D11: =IF(UNIT_SYSTEM="SI",13,1.88549059049272) -> 13 | E11: =IF(ISNUMBER(A11),A11/in_t,"") -> 0.7
A12: =IF(UNIT_SYSTEM="SI",16,0.62992125984252) -> 16 | B12: =IF(UNIT_SYSTEM="SI",102,14.7938492484813) -> 102 | C12: =IF(UNIT_SYSTEM="SI",14,2.03052832822293) -> 14 | D12: =IF(UNIT_SYSTEM="SI",12,1.74045285276251) -> 12 | E12: =IF(ISNUMBER(A12),A12/in_t,"") -> 0.8
A13: =IF(UNIT_SYSTEM="SI",18,0.708661417322835) -> 18 | B13: =IF(UNIT_SYSTEM="SI",96,13.9236228221001) -> 96 | C13: =IF(UNIT_SYSTEM="SI",12,1.74045285276251) -> 12 | D13: =IF(UNIT_SYSTEM="SI",11,1.5954151150323) -> 11 | E13: =IF(ISNUMBER(A13),A13/in_t,"") -> 0.9
A14: =IF(UNIT_SYSTEM="SI",20,0.78740157480315) -> 20 | B14: =IF(UNIT_SYSTEM="SI",90,13.0533963957188) -> 90 | C14: =IF(UNIT_SYSTEM="SI",10,1.45037737730209) -> 10 | D14: =IF(UNIT_SYSTEM="SI",10,1.45037737730209) -> 10 | E14: =IF(ISNUMBER(A14),A14/in_t,"") -> 1
E15: =IF(ISNUMBER(A15),A15/in_t,"")
E16: =IF(ISNUMBER(A16),A16/in_t,"")
E17: =IF(ISNUMBER(A17),A17/in_t,"")
E18: =IF(ISNUMBER(A18),A18/in_t,"")
E19: =IF(ISNUMBER(A19),A19/in_t,"")
E20: =IF(ISNUMBER(A20),A20/in_t,"")
E21: =IF(ISNUMBER(A21),A21/in_t,"")
E22: =IF(ISNUMBER(A22),A22/in_t,"")
E23: =IF(ISNUMBER(A23),A23/in_t,"")
E24: =IF(ISNUMBER(A24),A24/in_t,"")
E25: =IF(ISNUMBER(A25),A25/in_t,"")
E26: =IF(ISNUMBER(A26),A26/in_t,"")
... E53: =IF(ISNUMBER(A53),A53/in_t,"")

Sheet 6_Residual_Stress
A1: ="RESIDUAL STRESS - KPSCL1 / KPSCL2 / RPSCL ("&UNIT_SYSTEM&" UNITS)" -> RESIDUAL STRESS - KPSCL1 / KPSCL2 / RPSCL (SI UNITS)
A2: Annex 9D. Residual stress is held constant (not scaled) and enters KISR and the stress ratio R.
A3: Parameter | B3: Value | C3: Unit | D3: API 579 reference / note | E3: Status
A4: METHOD
A5: Residual stress method | B5: USER_DEFINED | C5: - | D5: USER_PROFILE uses the residual column of 5B_Stress_Profile | E5: INPUT
A6: USER_DEFINED
A7: Residual membrane stress, Rm (USER_DEFINED) | B7: =IF(UNIT_SYSTEM="SI",15,2.17556606595314) -> 15 | C7: =IF(UNIT_SYSTEM="SI","MPa","ksi") -> MPa | E7: INPUT
A8: Residual bending stress, Rb (USER_DEFINED) | B8: =IF(UNIT_SYSTEM="SI",5,0.725188688651046) -> 5 | C8: =IF(UNIT_SYSTEM="SI","MPa","ksi") -> MPa | E8: INPUT
A9: ANNEX_9D DATA (9D.3.1 required data)
A10: Material specification (9D.3.1) | B10: SA-516 Gr 70 | C10: - | D10: Suggestion list; free text allowed | E10: INPUT
A11: Base material SMYS (blank = material DB) | C11: =IF(UNIT_SYSTEM="SI","MPa","ksi") -> MPa | E11: INPUT
A12: Residual yield basis | B12: ESTIMATED_FROM_SMYS | C12: - | D12: Eq. 9D.1 or actual | E12: INPUT
A13: Actual yield strength | B13: =IF(UNIT_SYSTEM="SI",419,60.7708121089577) -> 419 | C13: =IF(UNIT_SYSTEM="SI","MPa","ksi") -> MPa | E13: INPUT
A14: Weld type | B14: BUTT_WELD | C14: - | E14: INPUT
A15: Weld joint configuration | B15: FULL_PENETRATION | C15: - | E15: INPUT
A16: Weld condition | B16: PWHT_UNIFORM | C16: - | E16: INPUT
A17: Stress direction relative to weld | B17: PERPENDICULAR | C17: - | E17: INPUT
A18: Pressure-test credit (9D.4.2) | B18: NONE | C18: - | E18: INPUT
A19: Residual yield strength sigma_ys_r | B19: =IF(in_ys_basis="ACTUAL",in_actual_ys,IF(ISNUMBER(in_smys_9d),in_smys_9d,db_SMYS)+IF(UNIT_SYSTEM="SI",69,10)) -> 419 | C19: =IF(UNIT_SYSTEM="SI","MPa","ksi") -> MPa | D19: Eq. 9D.1: SMYS + 69 MPa (SI) / + 10 ksi (FPS) | E19: CALC
A20: Uniform PWHT stress | B20: =IF(in_direction="PARALLEL",0.3,0.2)*calc_sysr -> 83.8 | C20: =IF(UNIT_SYSTEM="SI","MPa","ksi") -> MPa | D20: Eq. 9D.3 (perpendicular) / 9D.4 (parallel) | E20: CALC
A21: AS_WELDED PROFILE (applied as the actual through-wall profile)
A22: As-welded profile | B22: LONGITUDINAL_SEAM_PERPENDICULAR | C22: - | D22: KPTC: conservative uniform envelope; surface crack: actual profile | E22: INPUT
A23: Distance from weld centreline, y | B23: 0 | C23: =IF(UNIT_SYSTEM="SI","mm","in") -> mm | E23: INPUT
A24: Weld width, w | B24: =IF(UNIT_SYSTEM="SI",20,0.78740157480315) -> 20 | C24: =IF(UNIT_SYSTEM="SI","mm","in") -> mm | E24: INPUT
A25: Profile points | B25: 101 | C25: points | E25: INPUT

Sheet 7_Load_History
A1: ="LOAD HISTORY - VARIABLE AMPLITUDE BLOCKS ("&UNIT_SYSTEM&" UNITS)" -> LOAD HISTORY - VARIABLE AMPLITUDE BLOCKS (SI UNITS)
A2: Each block applies scale factors to the 5_Loads stresses (primary + secondary). Blank rows are ignored. Up to 40 blocks.
A3: Block | B3: Min scale | C3: Max scale | D3: Cycles / block | E3: Range (max-min) | F3: Fraction of cycles
A4: A | B4: 0 | C4: 0.7 | D4: 500 | E4: =IF(A4="","",C4-B4) -> 0.7 | F4: =IF(A4="","",D4/SUM($D$4:$D$43)) -> 0.5
A5: B | B5: 0.07 | C5: 0.8 | D5: 300 | E5: =IF(A5="","",C5-B5) -> 0.73 | F5: =IF(A5="","",D5/SUM($D$4:$D$43)) -> 0.3
A6: C | B6: 0.09 | C6: 0.9 | D6: 150 | E6: =IF(A6="","",C6-B6) -> 0.81 | F6: =IF(A6="","",D6/SUM($D$4:$D$43)) -> 0.15
A7: D | B7: 0.1 | C7: 1 | D7: 50 | E7: =IF(A7="","",C7-B7) -> 0.9 | F7: =IF(A7="","",D7/SUM($D$4:$D$43)) -> 0.05
E8: =IF(A8="","",C8-B8) | F8: =IF(A8="","",D8/SUM($D$4:$D$43))
E9: =IF(A9="","",C9-B9) | F9: =IF(A9="","",D9/SUM($D$4:$D$43))
E10: =IF(A10="","",C10-B10) | F10: =IF(A10="","",D10/SUM($D$4:$D$43))
E11: =IF(A11="","",C11-B11) | F11: =IF(A11="","",D11/SUM($D$4:$D$43))
E12: =IF(A12="","",C12-B12) | F12: =IF(A12="","",D12/SUM($D$4:$D$43))
E13: =IF(A13="","",C13-B13) | F13: =IF(A13="","",D13/SUM($D$4:$D$43))
E14: =IF(A14="","",C14-B14) | F14: =IF(A14="","",D14/SUM($D$4:$D$43))
E15: =IF(A15="","",C15-B15) | F15: =IF(A15="","",D15/SUM($D$4:$D$43))
E16: =IF(A16="","",C16-B16) | F16: =IF(A16="","",D16/SUM($D$4:$D$43))
E17: =IF(A17="","",C17-B17) | F17: =IF(A17="","",D17/SUM($D$4:$D$43))
E18: =IF(A18="","",C18-B18) | F18: =IF(A18="","",D18/SUM($D$4:$D$43))
E19: =IF(A19="","",C19-B19) | F19: =IF(A19="","",D19/SUM($D$4:$D$43))
... E43: =IF(A43="","",C43-B43) | F43: =IF(A43="","",D43/SUM($D$4:$D$43))
C45: Total cycles | D45: =SUM(D4:D43) -> 1000
A47: Load-block chart: see PLOTS/..._P09_Load_Spectrum after running the case.

Sheet 8_Controls
A1: ="CONTROLS - KPSCL1 / KPSCL2 / RPSCL ("&UNIT_SYSTEM&" UNITS)" -> CONTROLS - KPSCL1 / KPSCL2 / RPSCL (SI UNITS)
A2: Numerical controls and remaining-life acceptance (paragraph 9.5.1.2 STEP 6)
A3: Parameter | B3: Value | C3: Unit | D3: API 579 reference / note | E3: Status
A4: NUMERICAL CONTROLS
A5: Maximum cycles (guard) | B5: 5000000 | C5: cycles | E5: INPUT
A6: Maximum crack increment per step | B6: =IF(UNIT_SYSTEM="SI",0.02,0.00078740157480315) -> 0.02 | C6: =IF(UNIT_SYSTEM="SI","mm","in") -> mm | E6: INPUT
A7: Critical crack bisection iterations | B7: 100 | C7: iterations | E7: INPUT
A8: SIF-vs-crack points | B8: 250 | C8: points | E8: INPUT
A9: REMAINING LIFE ACCEPTANCE (9.5.1.2 STEP 6)
A10: Current flaw basis | B10: CURRENT_INSPECTED_FLAW | C10: - | D10: Remaining life is calculated from c0 to the limiting flaw size | E10: INPUT
A11: Required remaining life (cycles) | B11: 100000 | C11: cycles | D11: 9.5.1.2 STEP 6(1) | E11: INPUT
A12: In-service life margin factor | B12: 2 | C12: - | D12: Project factor (>= 1). Life must be >= factor x required life; allowable service life = life / factor | E12: INPUT
A13: Minimum calculated life for acceptance | B13: =in_required_life*in_life_margin -> 200000 | C13: cycles | D13: factor x required life | E13: CALC
A14: INSPECTION PLANNING (project basis - engineer approval required)
A15: Inspection fraction of allowable life | B15: 0.5 | C15: fraction | D15: Illustrative project default - not an API 579 prescribed value | E15: INPUT
A16: Inspection interval cap (blank = none) | C16: cycles | D16: Optional project / code cap, cycles | E16: INPUT
A17: Operating cycles per year (optional) | C17: cycles/yr | D17: Reports lives and interval in years | E17: INPUT

Sheet 9_Level3
A1: ="LEVEL3 - KPSCL1 / KPSCL2 / RPSCL ("&UNIT_SYSTEM&" UNITS)" -> LEVEL3 - KPSCL1 / KPSCL2 / RPSCL (SI UNITS)
A2: Paragraph 9.4.4 Level 3: Method A with uncertainty evaluation (9.4.4.2) and Method D ductile tearing (9.4.4.1(d))
A3: Parameter | B3: Value | C3: Unit | D3: API 579 reference / note | E3: Status
A4: METHOD A - SENSITIVITY ANALYSIS (9.4.4.2)
A5: Method A sensitivity analysis (9.4.4.2) | B5: YES | C5: - | D5: One-at-a-time variation of each input + combined adverse case | E5: INPUT
A6: Input varied (one at a time) | B6: Include | C6: Low change (%) | D6: High change (%) | E6: Status
A7: Primary stress (Pm, Pb, pc) | B7: YES | C7: -10 | D7: 10 | E7: INPUT
A8: Secondary stress (Sm, Sb) | B8: YES | C8: -20 | D8: 20 | E8: INPUT
A9: Residual stress (Rm, Rb) | B9: YES | C9: -30 | D9: 30 | E9: INPUT
A10: Initial flaw size (c0 or a0) | B10: YES | C10: -20 | D10: 20 | E10: INPUT
A11: Fracture toughness Kmat | B11: YES | C11: -20 | D11: 20 | E11: INPUT
A12: Yield and tensile strength | B12: YES | C12: -10 | D12: 10 | E12: INPUT
A13: Crack growth rate (Paris C) | B13: YES | C13: -50 | D13: 100 | E13: INPUT
A14: Threshold dKth | B14: YES | C14: -20 | D14: 20 | E14: INPUT
A15: Each case repeats the full Level 2 assessment, crack growth and remaining-life check. A combined adverse case (all inputs at their adverse end) is added automatically.
A16: PARTIAL SAFETY FACTOR CASE (project factors - 9.4.4.2)
A17: Partial safety factor case (9.4.4.2) | B17: NO | C17: - | D17: Project-defined factors - API 579 2021 gives no PSF table | E17: INPUT
A18: PSF on primary stress (multiplier) | B18: 1.2 | C18: factor | D18: Illustrative - set per project | E18: INPUT
A19: PSF on toughness (Kmat divided by) | B19: 1.2 | C19: factor | D19: Illustrative - set per project | E19: INPUT
A20: PSF on flaw size (c0 multiplier) | B20: 1.1 | C20: factor | D20: Illustrative - set per project | E20: INPUT
A21: METHOD D - DUCTILE TEARING (9.4.4.1(d), Annex 9F.4.13)
A22: Method D ductile tearing analysis (9.4.4.1(d)) | B22: YES | C22: - | D22: Only for materials with stable ductile tearing (upper-shelf ferritic, austenitic) | E22: INPUT
A23: J-R curve source | B23: TABLE_9F3 | C23: - | D23: TABLE_9F3 (typical data), CVN_9F130 (Eqs. 9F.130-9F.133) or PROJECT (approved test data) | E23: INPUT
A24: Table 9F.3 material record | B24: GENERIC_CS-1 | C24: - | D24: Typical values - actual data preferred | E24: INPUT
A25: Upper-shelf Charpy energy (CVN_9F130) | B25: =IF(UNIT_SYSTEM="SI",100,73.7562149277266) -> 100 | C25: =IF(UNIT_SYSTEM="SI","J","ft-lb") -> J | E25: INPUT
A26: J1mm basis (CVN_9F130) | B26: LOWER | C26: - | D26: Eq. 9F.88 (lower) or 9F.86 (median) | E26: INPUT
A27: Project J-R coefficient C_R | C27: =IF(UNIT_SYSTEM="SI","kJ/m² per mmⁿ","in-lb/in² per inⁿ") -> kJ/m² per mmⁿ | D27: J_R = C_R (da)^nR | E27: INPUT
A28: Project J-R exponent nR | C28: - | E28: INPUT
A29: Maximum tearing extension da | B29: =IF(UNIT_SYSTEM="SI",3,0.118110236220472) -> 3 | C29: =IF(UNIT_SYSTEM="SI","mm","in") -> mm | D29: Keep within the valid range of the J-R data | E29: INPUT
A30: Number of tearing points | B30: 60 | C30: points | E30: INPUT
A31: Maximum load factor searched | B31: 5 | C31: factor | D31: Primary-load factor range for the instability search | E31: INPUT
A32: Table 9F.3 record - material | B32: =IFERROR(INDEX(DB_JR_Curves!$B:$B,MATCH(in_jr_record,DB_JR_Curves!$A:$A,0)),"") -> Generic CS-1 | D32: Used when J-R source = TABLE_9F3 | E32: CALC
A33: Record test temperature | B33: =IFERROR(INDEX(DB_JR_Curves!$C:$C,MATCH(in_jr_record,DB_JR_Curves!$A:$A,0)),"") -> 288 | C33: =IF(UNIT_SYSTEM="SI","°C","°F") -> °C | D33: Used when J-R source = TABLE_9F3 | E33: CALC
A34: Record thickness | B34: =IFERROR(INDEX(DB_JR_Curves!$D:$D,MATCH(in_jr_record,DB_JR_Curves!$A:$A,0)),"") -> 25 | C34: =IF(UNIT_SYSTEM="SI","mm","in") -> mm | D34: Used when J-R source = TABLE_9F3 | E34: CALC
A35: Initiation toughness Ji | B35: =IFERROR(INDEX(DB_JR_Curves!$E:$E,MATCH(in_jr_record,DB_JR_Curves!$A:$A,0)),"") -> 61 | C35: =IF(UNIT_SYSTEM="SI","kJ/m²","in-lb/in²") -> kJ/m² | D35: Used when J-R source = TABLE_9F3 | E35: CALC
A36: Coefficient C_R | B36: =IFERROR(INDEX(DB_JR_Curves!$F:$F,MATCH(in_jr_record,DB_JR_Curves!$A:$A,0)),"") -> 129 | C36: =IF(UNIT_SYSTEM="SI","kJ/m² per mmⁿ","in-lb/in² per inⁿ") -> kJ/m² per mmⁿ | D36: Used when J-R source = TABLE_9F3 | E36: CALC
A37: Exponent nR | B37: =IFERROR(INDEX(DB_JR_Curves!$G:$G,MATCH(in_jr_record,DB_JR_Curves!$A:$A,0)),"") -> 0.277 | C37: - | D37: Used when J-R source = TABLE_9F3 | E37: CALC
A38: Method D is valid only for materials that tear in a stable ductile manner (ferritic steels on the upper shelf, austenitic stainless steels). Table 9F.3 data are typical values - use actual J-R test data when available.

Sheet DB_Materials
A1: material_id | B1: specification | C1: grade | D1: product_form | E1: condition | F1: material_class | G1: =IF(UNIT_SYSTEM="SI","SMYS (MPa)","SMYS (ksi)") -> SMYS (MPa) | H1: =IF(UNIT_SYSTEM="SI","SMTS (MPa)","SMTS (ksi)") -> SMTS (MPa) | I1: =IF(UNIT_SYSTEM="SI","E (MPa)","E (ksi)") -> E (MPa) | J1: exemption_curve | K1: lrmax_category | L1: default_growth_model | M1: default_toughness_method | N1: =IF(UNIT_SYSTEM="SI","Kmat (MPa√m)","Kmat (ksi√in)") -> Kmat (MPa√m) | O1: =IF(UNIT_SYSTEM="SI","Paris C (mm/cycle)","Paris C (in/cycle)") -> Paris C (mm/cycle) | P1: Paris n | Q1: =IF(UNIT_SYSTEM="SI","dKth (MPa√m)","dKth (ksi√in)") -> dKth (MPa√m) | R1: constraint | S1: note | T1: SMYS_MPa (source) | U1: SMYS_ksi (source) | V1: SMTS_MPa (source) | W1: SMTS_ksi (source) | X1: E_MPa (source) | Y1: E_ksi (source) | Z1: Kmat_MPa_sqrt_m (source) | AA1: Kmat_ksi_sqrt_in (source) | AB1: paris_C_mm_cycle (source) | AC1: paris_C_in_cycle (source) | AD1: dKth_MPa_sqrt_m (source) | AE1: dKth_ksi_sqrt_in (source)
A2: REFERENCE_CS_350 | B2: REFERENCE | C2: 350 MPa yield | D2: Generic | E2: - | F2: REFERENCE | G2: =IF(UNIT_SYSTEM="SI",IF(T2="","",T2),IF(U2="","",U2)) -> 350 | H2: =IF(UNIT_SYSTEM="SI",IF(V2="","",V2),IF(W2="","",W2)) -> 500 | I2: =IF(UNIT_SYSTEM="SI",IF(X2="","",X2),IF(Y2="","",Y2)) -> 200000 | J2: N/A | K2: FLOW_STRESS | L2: PROJECT_MATERIAL_DATA | M2: PROJECT_KMAT | N2: =IF(UNIT_SYSTEM="SI",IF(Z2="","",Z2),IF(AA2="","",AA2)) -> 100 | O2: =IF(UNIT_SYSTEM="SI",IF(AB2="","",AB2),IF(AC2="","",AC2)) -> 2e-09 | P2: 3 | Q2: =IF(UNIT_SYSTEM="SI",IF(AD2="","",AD2),IF(AE2="","",AE2)) -> 5 | R2: plane_strain | S2: ATLAS KPTC regression dataset (R1-R7 baseline). Not a material specification. FPS values are exact conversions. | T2: 350 | U2: 50.763208 | V2: 500 | W2: 72.518869 | X2: 200000 | Y2: 29007.548 | Z2: 100 | AA2: 91.004771 | AB2: 2e-09 | AC2: 1.0447294e-10 | AD2: 5 | AE2: 4.5502385
A3: SA-36 | B3: SA-36 | C3: - | D3: Plate/shape | E3: As-rolled | F3: CARBON_STEEL | G3: =IF(UNIT_SYSTEM="SI",IF(T3="","",T3),IF(U3="","",U3)) -> 250 | H3: =IF(UNIT_SYSTEM="SI",IF(V3="","",V3),IF(W3="","",W3)) -> 400 | I3: =IF(UNIT_SYSTEM="SI",IF(X3="","",X3),IF(Y3="","",Y3)) -> 200000 | J3: A | K3: C_MN_STEEL | L3: 9F4M_FERRITIC_PEARLITE_AIR | M3: 9F42_ASME_XI_LOWER | N3: =IF(UNIT_SYSTEM="SI",IF(Z3="","",Z3),IF(AA3="","",AA3)) | O3: =IF(UNIT_SYSTEM="SI",IF(AB3="","",AB3),IF(AC3="","",AC3)) | Q3: =IF(UNIT_SYSTEM="SI",IF(AD3="","",AD3),IF(AE3="","",AE3)) | R3: Exemption curve per API 579 Part 3 Table 3.2 (plates/shapes not listed -> A) | T3: 250 | U3: 36 | V3: 400 | W3: 58 | X3: 200000 | Y3: 29007.5 | AE3: plane_strain
A4: SA-285-C | B4: SA-285 | C4: Gr C | D4: Plate | E4: As-rolled | F4: CARBON_STEEL | G4: =IF(UNIT_SYSTEM="SI",IF(T4="","",T4),IF(U4="","",U4)) -> 205 | H4: =IF(UNIT_SYSTEM="SI",IF(V4="","",V4),IF(W4="","",W4)) -> 380 | I4: =IF(UNIT_SYSTEM="SI",IF(X4="","",X4),IF(Y4="","",Y4)) -> 200000 | J4: A | K4: C_MN_STEEL | L4: 9F4M_FERRITIC_PEARLITE_AIR | M4: 9F42_ASME_XI_LOWER | N4: =IF(UNIT_SYSTEM="SI",IF(Z4="","",Z4),IF(AA4="","",AA4)) | O4: =IF(UNIT_SYSTEM="SI",IF(AB4="","",AB4),IF(AC4="","",AC4)) | Q4: =IF(UNIT_SYSTEM="SI",IF(AD4="","",AD4),IF(AE4="","",AE4)) | R4: Exemption curve per API 579 Part 3 Table 3.2 (Gr A/B are Curve B; Gr C not listed -> A) | T4: 205 | U4: 30 | V4: 380 | W4: 55 | X4: 200000 | Y4: 29007.5 | AE4: plane_strain
A5: SA-515-60 | B5: SA-515 | C5: Gr 60 | D5: Plate | E5: As-rolled | F5: CARBON_STEEL | G5: =IF(UNIT_SYSTEM="SI",IF(T5="","",T5),IF(U5="","",U5)) -> 220 | H5: =IF(UNIT_SYSTEM="SI",IF(V5="","",V5),IF(W5="","",W5)) -> 415 | I5: =IF(UNIT_SYSTEM="SI",IF(X5="","",X5),IF(Y5="","",Y5)) -> 200000 | J5: B | K5: C_MN_STEEL | L5: 9F4M_FERRITIC_PEARLITE_AIR | M5: 9F42_ASME_XI_LOWER | N5: =IF(UNIT_SYSTEM="SI",IF(Z5="","",Z5),IF(AA5="","",AA5)) | O5: =IF(UNIT_SYSTEM="SI",IF(AB5="","",AB5),IF(AC5="","",AC5)) | Q5: =IF(UNIT_SYSTEM="SI",IF(AD5="","",AD5),IF(AE5="","",AE5)) | R5: Exemption curve per API 579 Part 3 Table 3.2 | T5: 220 | U5: 32 | V5: 415 | W5: 60 | X5: 200000 | Y5: 29007.5 | AE5: plane_strain
A6: SA-515-70 | B6: SA-515 | C6: Gr 70 | D6: Plate | E6: As-rolled | F6: CARBON_STEEL | G6: =IF(UNIT_SYSTEM="SI",IF(T6="","",T6),IF(U6="","",U6)) -> 260 | H6: =IF(UNIT_SYSTEM="SI",IF(V6="","",V6),IF(W6="","",W6)) -> 485 | I6: =IF(UNIT_SYSTEM="SI",IF(X6="","",X6),IF(Y6="","",Y6)) -> 200000 | J6: A | K6: C_MN_STEEL | L6: 9F4M_FERRITIC_PEARLITE_AIR | M6: 9F42_ASME_XI_LOWER | N6: =IF(UNIT_SYSTEM="SI",IF(Z6="","",Z6),IF(AA6="","",AA6)) | O6: =IF(UNIT_SYSTEM="SI",IF(AB6="","",AB6),IF(AC6="","",AC6)) | Q6: =IF(UNIT_SYSTEM="SI",IF(AD6="","",AD6),IF(AE6="","",AE6)) | R6: Exemption curve per API 579 Part 3 Table 3.2 (not listed -> A) | T6: 260 | U6: 38 | V6: 485 | W6: 70 | X6: 200000 | Y6: 29007.5 | AE6: plane_strain
A7: SA-516-55 | B7: SA-516 | C7: Gr 55 | D7: Plate | E7: Not normalized | F7: CARBON_STEEL | G7: =IF(UNIT_SYSTEM="SI",IF(T7="","",T7),IF(U7="","",U7)) -> 205 | H7: =IF(UNIT_SYSTEM="SI",IF(V7="","",V7),IF(W7="","",W7)) -> 380 | I7: =IF(UNIT_SYSTEM="SI",IF(X7="","",X7),IF(Y7="","",Y7)) -> 200000 | J7: C | K7: C_MN_STEEL | L7: 9F4M_FERRITIC_PEARLITE_AIR | M7: 9F42_ASME_XI_LOWER | N7: =IF(UNIT_SYSTEM="SI",IF(Z7="","",Z7),IF(AA7="","",AA7)) | O7: =IF(UNIT_SYSTEM="SI",IF(AB7="","",AB7),IF(AC7="","",AC7)) | Q7: =IF(UNIT_SYSTEM="SI",IF(AD7="","",AD7),IF(AE7="","",AE7)) | R7: Exemption curve per API 579 Part 3 Table 3.2 | T7: 205 | U7: 30 | V7: 380 | W7: 55 | X7: 200000 | Y7: 29007.5 | AE7: plane_strain
A8: SA-516-60 | B8: SA-516 | C8: Gr 60 | D8: Plate | E8: Not normalized | F8: CARBON_STEEL | G8: =IF(UNIT_SYSTEM="SI",IF(T8="","",T8),IF(U8="","",U8)) -> 220 | H8: =IF(UNIT_SYSTEM="SI",IF(V8="","",V8),IF(W8="","",W8)) -> 415 | I8: =IF(UNIT_SYSTEM="SI",IF(X8="","",X8),IF(Y8="","",Y8)) -> 200000 | J8: C | K8: C_MN_STEEL | L8: 9F4M_FERRITIC_PEARLITE_AIR | M8: 9F42_ASME_XI_LOWER | N8: =IF(UNIT_SYSTEM="SI",IF(Z8="","",Z8),IF(AA8="","",AA8)) | O8: =IF(UNIT_SYSTEM="SI",IF(AB8="","",AB8),IF(AC8="","",AC8)) | Q8: =IF(UNIT_SYSTEM="SI",IF(AD8="","",AD8),IF(AE8="","",AE8)) | R8: Exemption curve per API 579 Part 3 Table 3.2 | T8: 220 | U8: 32 | V8: 415 | W8: 60 | X8: 200000 | Y8: 29007.5 | AE8: plane_strain
A9: SA-516-65 | B9: SA-516 | C9: Gr 65 | D9: Plate | E9: Not normalized | F9: CARBON_STEEL | G9: =IF(UNIT_SYSTEM="SI",IF(T9="","",T9),IF(U9="","",U9)) -> 240 | H9: =IF(UNIT_SYSTEM="SI",IF(V9="","",V9),IF(W9="","",W9)) -> 450 | I9: =IF(UNIT_SYSTEM="SI",IF(X9="","",X9),IF(Y9="","",Y9)) -> 200000 | J9: B | K9: C_MN_STEEL | L9: 9F4M_FERRITIC_PEARLITE_AIR | M9: 9F42_ASME_XI_LOWER | N9: =IF(UNIT_SYSTEM="SI",IF(Z9="","",Z9),IF(AA9="","",AA9)) | O9: =IF(UNIT_SYSTEM="SI",IF(AB9="","",AB9),IF(AC9="","",AC9)) | Q9: =IF(UNIT_SYSTEM="SI",IF(AD9="","",AD9),IF(AE9="","",AE9)) | R9: Exemption curve per API 579 Part 3 Table 3.2 | T9: 240 | U9: 35 | V9: 450 | W9: 65 | X9: 200000 | Y9: 29007.5 | AE9: plane_strain
A10: SA-516-70 | B10: SA-516 | C10: Gr 70 | D10: Plate | E10: Not normalized | F10: CARBON_STEEL | G10: =IF(UNIT_SYSTEM="SI",IF(T10="","",T10),IF(U10="","",U10)) -> 260 | H10: =IF(UNIT_SYSTEM="SI",IF(V10="","",V10),IF(W10="","",W10)) -> 485 | I10: =IF(UNIT_SYSTEM="SI",IF(X10="","",X10),IF(Y10="","",Y10)) -> 200000 | J10: B | K10: C_MN_STEEL | L10: 9F4M_FERRITIC_PEARLITE_AIR | M10: 9F42_ASME_XI_LOWER | N10: =IF(UNIT_SYSTEM="SI",IF(Z10="","",Z10),IF(AA10="","",AA10)) | O10: =IF(UNIT_SYSTEM="SI",IF(AB10="","",AB10),IF(AC10="","",AC10)) | Q10: =IF(UNIT_SYSTEM="SI",IF(AD10="","",AD10),IF(AE10="","",AE10)) | R10: Exemption curve per API 579 Part 3 Table 3.2 | T10: 260 | U10: 38 | V10: 485 | W10: 70 | X10: 200000 | Y10: 29007.5 | AE10: plane_strain
A11: SA-516-70N | B11: SA-516 | C11: Gr 70 | D11: Plate | E11: Normalized | F11: CARBON_STEEL | G11: =IF(UNIT_SYSTEM="SI",IF(T11="","",T11),IF(U11="","",U11)) -> 260 | H11: =IF(UNIT_SYSTEM="SI",IF(V11="","",V11),IF(W11="","",W11)) -> 485 | I11: =IF(UNIT_SYSTEM="SI",IF(X11="","",X11),IF(Y11="","",Y11)) -> 200000 | J11: D | K11: C_MN_STEEL | L11: 9F4M_FERRITIC_PEARLITE_AIR | M11: 9F42_ASME_XI_LOWER | N11: =IF(UNIT_SYSTEM="SI",IF(Z11="","",Z11),IF(AA11="","",AA11)) | O11: =IF(UNIT_SYSTEM="SI",IF(AB11="","",AB11),IF(AC11="","",AC11)) | Q11: =IF(UNIT_SYSTEM="SI",IF(AD11="","",AD11),IF(AE11="","",AE11)) | R11: Exemption curve per API 579 Part 3 Table 3.2 | T11: 260 | U11: 38 | V11: 485 | W11: 70 | X11: 200000 | Y11: 29007.5 | AE11: plane_strain
A12: SA-537-CL1 | B12: SA-537 | C12: Cl 1 | D12: Plate | E12: Normalized | F12: CARBON_STEEL | G12: =IF(UNIT_SYSTEM="SI",IF(T12="","",T12),IF(U12="","",U12)) -> 345 | H12: =IF(UNIT_SYSTEM="SI",IF(V12="","",V12),IF(W12="","",W12)) -> 485 | I12: =IF(UNIT_SYSTEM="SI",IF(X12="","",X12),IF(Y12="","",Y12)) -> 200000 | J12: D | K12: C_MN_STEEL | L12: 9F4M_FERRITIC_PEARLITE_AIR | M12: 9F42_ASME_XI_LOWER | N12: =IF(UNIT_SYSTEM="SI",IF(Z12="","",Z12),IF(AA12="","",AA12)) | O12: =IF(UNIT_SYSTEM="SI",IF(AB12="","",AB12),IF(AC12="","",AC12)) | Q12: =IF(UNIT_SYSTEM="SI",IF(AD12="","",AD12),IF(AE12="","",AE12)) | R12: Exemption curve per API 579 Part 3 Table 3.2; SMYS for t <= 65 mm (2.5 in) | T12: 345 | U12: 50 | V12: 485 | W12: 70 | X12: 200000 | Y12: 29007.5 | AE12: plane_strain
A13: SA-106-B | B13: SA-106 | C13: Gr B | D13: Seamless pipe | E13: - | F13: CARBON_STEEL | G13: =IF(UNIT_SYSTEM="SI",IF(T13="","",T13),IF(U13="","",U13)) -> 240 | H13: =IF(UNIT_SYSTEM="SI",IF(V13="","",V13),IF(W13="","",W13)) -> 415 | I13: =IF(UNIT_SYSTEM="SI",IF(X13="","",X13),IF(Y13="","",Y13)) -> 200000 | J13: B | K13: C_MN_STEEL | L13: 9F4M_FERRITIC_PEARLITE_AIR | M13: 9F42_ASME_XI_LOWER | N13: =IF(UNIT_SYSTEM="SI",IF(Z13="","",Z13),IF(AA13="","",AA13)) | O13: =IF(UNIT_SYSTEM="SI",IF(AB13="","",AB13),IF(AC13="","",AC13)) | Q13: =IF(UNIT_SYSTEM="SI",IF(AD13="","",AD13),IF(AE13="","",AE13)) | R13: Exemption curve per API 579 Part 3 Table 3.2 (all pipe -> B) | T13: 240 | U13: 35 | V13: 415 | W13: 60 | X13: 200000 | Y13: 29007.5 | AE13: plane_strain
A14: SA-106-C | B14: SA-106 | C14: Gr C | D14: Seamless pipe | E14: - | F14: CARBON_STEEL | G14: =IF(UNIT_SYSTEM="SI",IF(T14="","",T14),IF(U14="","",U14)) -> 275 | H14: =IF(UNIT_SYSTEM="SI",IF(V14="","",V14),IF(W14="","",W14)) -> 485 | I14: =IF(UNIT_SYSTEM="SI",IF(X14="","",X14),IF(Y14="","",Y14)) -> 200000 | J14: B | K14: C_MN_STEEL | L14: 9F4M_FERRITIC_PEARLITE_AIR | M14: 9F42_ASME_XI_LOWER | N14: =IF(UNIT_SYSTEM="SI",IF(Z14="","",Z14),IF(AA14="","",AA14)) | O14: =IF(UNIT_SYSTEM="SI",IF(AB14="","",AB14),IF(AC14="","",AC14)) | Q14: =IF(UNIT_SYSTEM="SI",IF(AD14="","",AD14),IF(AE14="","",AE14)) | R14: Exemption curve per API 579 Part 3 Table 3.2 (all pipe -> B) | T14: 275 | U14: 40 | V14: 485 | W14: 70 | X14: 200000 | Y14: 29007.5 | AE14: plane_strain
... A30: SA-533-B-CL1 | B30: SA-533 | C30: Type B Cl 1 | D30: Plate | E30: Q&T | F30: LOW_ALLOY_STEEL | G30: =IF(UNIT_SYSTEM="SI",IF(T30="","",T30),IF(U30="","",U30)) -> 345 | H30: =IF(UNIT_SYSTEM="SI",IF(V30="","",V30),IF(W30="","",W30)) -> 550 | I30: =IF(UNIT_SYSTEM="SI",IF(X30="","",X30),IF(Y30="","",Y30)) -> 200000 | J30: C | K30: FLOW_STRESS | L30: 9F4M_FERRITIC_PEARLITE_AIR | M30: 9F43_MASTER_CURVE | N30: =IF(UNIT_SYSTEM="SI",IF(Z30="","",Z30),IF(AA30="","",AA30)) | O30: =IF(UNIT_SYSTEM="SI",IF(AB30="","",AB30),IF(AC30="","",AC30)) | Q30: =IF(UNIT_SYSTEM="SI",IF(AD30="","",AD30),IF(AE30="","",AE30)) | R30: Exemption curve per API 579 Part 3 Table 3.2 | T30: 345 | U30: 50 | V30: 550 | W30: 80 | X30: 200000 | Y30: 29007.5 | AE30: plane_strain
A31: SA-240-304 | B31: SA-240 | C31: 304 | D31: Plate | E31: Solution annealed | F31: AUSTENITIC_SS | G31: =IF(UNIT_SYSTEM="SI",IF(T31="","",T31),IF(U31="","",U31)) -> 205 | H31: =IF(UNIT_SYSTEM="SI",IF(V31="","",V31),IF(W31="","",W31)) -> 515 | I31: =IF(UNIT_SYSTEM="SI",IF(X31="","",X31),IF(Y31="","",Y31)) -> 195000 | J31: N/A | K31: AUSTENITIC_SS | L31: 9F4M_AUSTENITIC_SS_AIR | M31: 9F412_AUSTENITIC_JC | N31: =IF(UNIT_SYSTEM="SI",IF(Z31="","",Z31),IF(AA31="","",AA31)) | O31: =IF(UNIT_SYSTEM="SI",IF(AB31="","",AB31),IF(AC31="","",AC31)) | Q31: =IF(UNIT_SYSTEM="SI",IF(AD31="","",AD31),IF(AE31="","",AE31)) | R31: Austenitic: no exemption curve | T31: 205 | U31: 30 | V31: 515 | W31: 75 | X31: 195000 | Y31: 28282.4 | AE31: plane_strain
A32: SA-240-304L | B32: SA-240 | C32: 304L | D32: Plate | E32: Solution annealed | F32: AUSTENITIC_SS | G32: =IF(UNIT_SYSTEM="SI",IF(T32="","",T32),IF(U32="","",U32)) -> 170 | H32: =IF(UNIT_SYSTEM="SI",IF(V32="","",V32),IF(W32="","",W32)) -> 485 | I32: =IF(UNIT_SYSTEM="SI",IF(X32="","",X32),IF(Y32="","",Y32)) -> 195000 | J32: N/A | K32: AUSTENITIC_SS | L32: 9F4M_AUSTENITIC_SS_AIR | M32: 9F412_AUSTENITIC_JC | N32: =IF(UNIT_SYSTEM="SI",IF(Z32="","",Z32),IF(AA32="","",AA32)) | O32: =IF(UNIT_SYSTEM="SI",IF(AB32="","",AB32),IF(AC32="","",AC32)) | Q32: =IF(UNIT_SYSTEM="SI",IF(AD32="","",AD32),IF(AE32="","",AE32)) | R32: Austenitic: no exemption curve | T32: 170 | U32: 25 | V32: 485 | W32: 70 | X32: 195000 | Y32: 28282.4 | AE32: plane_strain
A33: SA-240-316 | B33: SA-240 | C33: 316 | D33: Plate | E33: Solution annealed | F33: AUSTENITIC_SS | G33: =IF(UNIT_SYSTEM="SI",IF(T33="","",T33),IF(U33="","",U33)) -> 205 | H33: =IF(UNIT_SYSTEM="SI",IF(V33="","",V33),IF(W33="","",W33)) -> 515 | I33: =IF(UNIT_SYSTEM="SI",IF(X33="","",X33),IF(Y33="","",Y33)) -> 195000 | J33: N/A | K33: AUSTENITIC_SS | L33: 9F4M_AUSTENITIC_SS_AIR | M33: 9F412_AUSTENITIC_JC | N33: =IF(UNIT_SYSTEM="SI",IF(Z33="","",Z33),IF(AA33="","",AA33)) | O33: =IF(UNIT_SYSTEM="SI",IF(AB33="","",AB33),IF(AC33="","",AC33)) | Q33: =IF(UNIT_SYSTEM="SI",IF(AD33="","",AD33),IF(AE33="","",AE33)) | R33: Austenitic: no exemption curve | T33: 205 | U33: 30 | V33: 515 | W33: 75 | X33: 195000 | Y33: 28282.4 | AE33: plane_strain
A34: SA-240-316L | B34: SA-240 | C34: 316L | D34: Plate | E34: Solution annealed | F34: AUSTENITIC_SS | G34: =IF(UNIT_SYSTEM="SI",IF(T34="","",T34),IF(U34="","",U34)) -> 170 | H34: =IF(UNIT_SYSTEM="SI",IF(V34="","",V34),IF(W34="","",W34)) -> 485 | I34: =IF(UNIT_SYSTEM="SI",IF(X34="","",X34),IF(Y34="","",Y34)) -> 195000 | J34: N/A | K34: AUSTENITIC_SS | L34: 9F4M_AUSTENITIC_SS_AIR | M34: 9F412_AUSTENITIC_JC | N34: =IF(UNIT_SYSTEM="SI",IF(Z34="","",Z34),IF(AA34="","",AA34)) | O34: =IF(UNIT_SYSTEM="SI",IF(AB34="","",AB34),IF(AC34="","",AC34)) | Q34: =IF(UNIT_SYSTEM="SI",IF(AD34="","",AD34),IF(AE34="","",AE34)) | R34: Austenitic: no exemption curve | T34: 170 | U34: 25 | V34: 485 | W34: 70 | X34: 195000 | Y34: 28282.4 | AE34: plane_strain
A35: SA-240-321 | B35: SA-240 | C35: 321 | D35: Plate | E35: Solution annealed | F35: AUSTENITIC_SS | G35: =IF(UNIT_SYSTEM="SI",IF(T35="","",T35),IF(U35="","",U35)) -> 205 | H35: =IF(UNIT_SYSTEM="SI",IF(V35="","",V35),IF(W35="","",W35)) -> 515 | I35: =IF(UNIT_SYSTEM="SI",IF(X35="","",X35),IF(Y35="","",Y35)) -> 195000 | J35: N/A | K35: AUSTENITIC_SS | L35: 9F4M_AUSTENITIC_SS_AIR | M35: 9F412_AUSTENITIC_JC | N35: =IF(UNIT_SYSTEM="SI",IF(Z35="","",Z35),IF(AA35="","",AA35)) | O35: =IF(UNIT_SYSTEM="SI",IF(AB35="","",AB35),IF(AC35="","",AC35)) | Q35: =IF(UNIT_SYSTEM="SI",IF(AD35="","",AD35),IF(AE35="","",AE35)) | R35: Austenitic: no exemption curve | T35: 205 | U35: 30 | V35: 515 | W35: 75 | X35: 195000 | Y35: 28282.4 | AE35: plane_strain
A36: SA-240-347 | B36: SA-240 | C36: 347 | D36: Plate | E36: Solution annealed | F36: AUSTENITIC_SS | G36: =IF(UNIT_SYSTEM="SI",IF(T36="","",T36),IF(U36="","",U36)) -> 205 | H36: =IF(UNIT_SYSTEM="SI",IF(V36="","",V36),IF(W36="","",W36)) -> 515 | I36: =IF(UNIT_SYSTEM="SI",IF(X36="","",X36),IF(Y36="","",Y36)) -> 195000 | J36: N/A | K36: AUSTENITIC_SS | L36: 9F4M_AUSTENITIC_SS_AIR | M36: 9F412_AUSTENITIC_JC | N36: =IF(UNIT_SYSTEM="SI",IF(Z36="","",Z36),IF(AA36="","",AA36)) | O36: =IF(UNIT_SYSTEM="SI",IF(AB36="","",AB36),IF(AC36="","",AC36)) | Q36: =IF(UNIT_SYSTEM="SI",IF(AD36="","",AD36),IF(AE36="","",AE36)) | R36: Austenitic: no exemption curve | T36: 205 | U36: 30 | V36: 515 | W36: 75 | X36: 195000 | Y36: 28282.4 | AE36: plane_strain
A37: SA-312-TP304 | B37: SA-312 | C37: TP304 | D37: Pipe | E37: Solution annealed | F37: AUSTENITIC_SS | G37: =IF(UNIT_SYSTEM="SI",IF(T37="","",T37),IF(U37="","",U37)) -> 205 | H37: =IF(UNIT_SYSTEM="SI",IF(V37="","",V37),IF(W37="","",W37)) -> 515 | I37: =IF(UNIT_SYSTEM="SI",IF(X37="","",X37),IF(Y37="","",Y37)) -> 195000 | J37: N/A | K37: AUSTENITIC_SS | L37: 9F4M_AUSTENITIC_SS_AIR | M37: 9F412_AUSTENITIC_JC | N37: =IF(UNIT_SYSTEM="SI",IF(Z37="","",Z37),IF(AA37="","",AA37)) | O37: =IF(UNIT_SYSTEM="SI",IF(AB37="","",AB37),IF(AC37="","",AC37)) | Q37: =IF(UNIT_SYSTEM="SI",IF(AD37="","",AD37),IF(AE37="","",AE37)) | R37: Austenitic: no exemption curve | T37: 205 | U37: 30 | V37: 515 | W37: 75 | X37: 195000 | Y37: 28282.4 | AE37: plane_strain
A38: SA-312-TP316L | B38: SA-312 | C38: TP316L | D38: Pipe | E38: Solution annealed | F38: AUSTENITIC_SS | G38: =IF(UNIT_SYSTEM="SI",IF(T38="","",T38),IF(U38="","",U38)) -> 170 | H38: =IF(UNIT_SYSTEM="SI",IF(V38="","",V38),IF(W38="","",W38)) -> 485 | I38: =IF(UNIT_SYSTEM="SI",IF(X38="","",X38),IF(Y38="","",Y38)) -> 195000 | J38: N/A | K38: AUSTENITIC_SS | L38: 9F4M_AUSTENITIC_SS_AIR | M38: 9F412_AUSTENITIC_JC | N38: =IF(UNIT_SYSTEM="SI",IF(Z38="","",Z38),IF(AA38="","",AA38)) | O38: =IF(UNIT_SYSTEM="SI",IF(AB38="","",AB38),IF(AC38="","",AC38)) | Q38: =IF(UNIT_SYSTEM="SI",IF(AD38="","",AD38),IF(AE38="","",AE38)) | R38: Austenitic: no exemption curve | T38: 170 | U38: 25 | V38: 485 | W38: 70 | X38: 195000 | Y38: 28282.4 | AE38: plane_strain
A40: Source: data/materials_db.csv. Specified minimum strengths per material specification (confirm against the current edition); exemption curves per API 579 Part 3 Table 3.2; E values typical. Values follow the Unit System drop-down on the Cover sheet.

Sheet DB_Growth
A1: model_id | B1: R_range | C1: API table | D1: equation | E1: description | F1: applicability | G1: =IF(UNIT_SYSTEM="SI","C1 (mm/cycle)","C1 (in/cycle)") -> C1 (mm/cycle) | H1: n1 | I1: =IF(UNIT_SYSTEM="SI","C2 (mm/cycle)","C2 (in/cycle)") -> C2 (mm/cycle) | J1: n2 | K1: =IF(UNIT_SYSTEM="SI","dK transition (MPa√m)","dK transition (ksi√in)") -> dK transition (MPa√m) | L1: =IF(UNIT_SYSTEM="SI","dKth (MPa√m)","dKth (ksi√in)") -> dKth (MPa√m) | M1: C1_SI_mm_cycle (source) | N1: C1_US_in_cycle (source) | O1: C2_SI_mm_cycle (source) | P1: C2_US_in_cycle (source) | Q1: dKtran_SI (source) | R1: dKtran_US (source) | S1: dKth_SI (source) | T1: dKth_US (source)
A2: PROJECT_MATERIAL_DATA | B2: ALL | C2: Material DB | D2: PARIS_9F135 | E2: C, n, dKth from selected material record | F2: Approved material-specific data | G2: =IF(UNIT_SYSTEM="SI",IF(M2="","",M2),IF(N2="","",N2)) | I2: =IF(UNIT_SYSTEM="SI",IF(O2="","",O2),IF(P2="","",P2)) | K2: =IF(UNIT_SYSTEM="SI",IF(Q2="","",Q2),IF(R2="","",R2)) | L2: =IF(UNIT_SYSTEM="SI",IF(S2="","",S2),IF(T2="","",T2))
A3: PROJECT_USER_PARIS | B3: ALL | C3: Project | D3: PARIS_9F135 | E3: User-entered Paris C, n, dKth (4_Crack_Growth sheet) | F3: Approved project data | G3: =IF(UNIT_SYSTEM="SI",IF(M3="","",M3),IF(N3="","",N3)) | I3: =IF(UNIT_SYSTEM="SI",IF(O3="","",O3),IF(P3="","",P3)) | K3: =IF(UNIT_SYSTEM="SI",IF(Q3="","",Q3),IF(R3="","",R3)) | L3: =IF(UNIT_SYSTEM="SI",IF(S3="","",S3),IF(T3="","",T3))
A4: 9F4M_MARTENSITIC_AIR | B4: ALL | C4: =IF(UNIT_SYSTEM="SI","9F.4M","9F.4") -> 9F.4M | D4: PARIS_9F135 | E4: Barsom - martensitic steel, air | F4: Sy 552-2068 MPa (80-300 ksi); room temperature; air/non-aggressive | G4: =IF(UNIT_SYSTEM="SI",IF(M4="","",M4),IF(N4="","",N4)) -> 1.36e-07 | H4: 2.25 | I4: =IF(UNIT_SYSTEM="SI",IF(O4="","",O4),IF(P4="","",P4)) | K4: =IF(UNIT_SYSTEM="SI",IF(Q4="","",Q4),IF(R4="","",R4)) | L4: =IF(UNIT_SYSTEM="SI",IF(S4="","",S4),IF(T4="","",T4)) -> 7.0*(1-0.85*R) | M4: 1.36e-07 | N4: 6.6e-09 | S4: 7.0*(1-0.85*R) | T4: 6.37*(1-0.85*R)
